Workbook

Sheet DPR ( 02-APR-2026 )
A4: Daily Production Report : 02-APR-2026
A5: Product | C5: Oil | P5: Total Oil | Q5: Condensate | R5: Total Condensate | S5: Gas | AF5: Total Gas | AG5: Total Oil, Condensate and Gas
A6: Asset | C6: Azerbaijan, ACG | D6: Brazil, BC-10 | E6: Brazil, BC-60 asset | F6: Colombia, CPO-5 | G6: Colombia, MECL | H6: Russia, Imperial Energy | I6: Russia, Sakhalin-1 | J6: Russia, Vankor | K6: South Sudan, GPOC | L6: South Sudan, SPOC | M6: UAE, Lower Zakum Concession | N6: Venezuela, Carabobo | O6: Venezuala, San Cristobal | Q6: Vietnam, Block B06.1 | S6: Azerbaijan, ACG | T6: Brazil, BC-10 | U6: Brazil, BC-60 asset | V6: Colombia, CPO-5 | W6: Colombia, MECL | X6: Myanmar, Block A1 | Y6: Myanmar, Block A3 | Z6: Russia, Imperial Energy | AA6: Russia, Sakhalin-1 | AB6: Russia, Vankor | AC6: Venezuela, Carabobo | AD6: Venezuala, San Cristobal | AE6: Vietnam, Block B06.1
A7: ONGC VideshShare (%) | C7: 2.925 | D7: 27 | E7: 0.232 | F7: 70 | G7: 50 | H7: 100 | I7: 20 | J7: 26 | K7: 25 | L7: 24.125 | M7: 4 | N7: 11 | O7: 40 | Q7: 45 | S7: 2.925 | T7: 27 | U7: 0.232 | V7: 70 | W7: 50 | X7: 17 | Y7: 17 | Z7: 100 | AA7: 20 | AB7: 26 | AC7: 11 | AD7: 40 | AE7: 45
A8: Conversion Factor (bbl/tonnes) | C8: 7.444606 | D8: 6.664992 | E8: 6.665 | F8: 7.37787 | G8: 6.779987 | H8: 7.729118 | I8: 7.323245 | J8: 7.44 | K8: 7.3 | L8: 6.8 | M8: 7.62 | N8: 6.24 | O8: 6.570004 | Q8: 8.344884
A9: Consortium Level | C9: JV | P9: ONGC Videsh | Q9: JV | R9: ONGC Videsh | S9: JV | AF9: ONGC Videsh | AG9: ONGC Videsh
A10: Date/Unit | C10: BOPD | P10: BOPD | Q10: BCPD | R10: BCPD | S10: MMSCMD | AF10: MMSCMD | AG10: BOEPD
A11: 46082 | C11: 298742 | D11: 35020.35 | E11: 128511.9 | F11: 22778 | G11: 4676 | H11: 2062.491 | I11: 191127 | J11: 151392.3 | K11: 53770.45 | L11: 12231 | M11: 449370 | N11: 6969 | O11: 2813 | P11: 152684.27 | Q11: 0 | R11: 0 | S11: 15.065439 | T11: 0.455 | U11: 7.25 | V11: 0.0035081 | W11: 0 | X11: 10.926204 | Y11: 3.3771105 | Z11: 0.285765 | AA11: 12.344143 | AB11: 8.835598 | AC11: 0.229745 | AD11: 0.1062606 | AE11: 0 | AF11: 8.1339784 | AG11: 203846.99
A12: 46083 | C12: 347692 | D12: 35020.35 | E12: 129142.7 | F12: 22742 | G12: 4629 | H12: 2066.894 | I12: 186020 | J12: 155633.7 | K12: 47883 | L12: 10461 | M12: 448623 | N12: 7094 | O12: 2834 | P12: 152247.98 | Q12: 0 | R12: 0 | S12: 15.190085 | T12: 0.455 | U12: 7.409 | V12: 0.0036366 | W12: 0 | X12: 11.463201 | Y12: 3.3881303 | Z12: 0.283278 | AA12: 12.377925 | AB12: 2.532222 | AC12: 0.2286119 | AD12: 0.1064306 | AE12: 0 | AF12: 6.596581 | AG12: 193740.47
A13: 46084 | C13: 333563 | D13: 34808.13 | E13: 126447.19 | F13: 22703 | G13: 4601 | H13: 2066.177 | I13: 182775 | J13: 155914.2 | K13: 52492.2 | L13: 9818 | M13: 452133 | N13: 7082 | O13: 2885 | P13: 152309.72 | Q13: 0 | R13: 0 | S13: 15.290368 | T13: 0.454 | U13: 7.274 | V13: 0.0036764 | W13: 0 | X13: 11.219264 | Y13: 3.3860623 | Z13: 0.28068 | AA13: 12.343661 | AB13: 2.674275 | AC13: 0.2223796 | AD13: 0.0939943 | AE13: 0 | AF13: 6.5789611 | AG13: 193691.39
A14: 46085 | C14: 338038 | D14: 34857.69 | E14: 129037.41 | F14: 22672 | G14: 4563 | H14: 2065.619 | I14: 182807 | J14: 144387.3 | K14: 52390.71 | L14: 12419 | M14: 428904 | N14: 7155 | O14: 2912 | P14: 149119.94 | Q14: 0 | R14: 0 | S14: 15.092351 | T14: 0.461 | U14: 7.389 | V14: 0.0036038 | W14: 0 | X14: 11.215212 | Y14: 3.3935411 | Z14: 0.277103 | AA14: 12.261911 | AB14: 2.765916 | AC14: 0.2254958 | AD14: 0.092153 | AE14: 0 | AF14: 6.5793635 | AG14: 190504.14
A15: 46086 | C15: 337092 | D15: 35257.04 | E15: 126412.08 | F15: 22656 | G15: 4591 | H15: 2079.127 | I15: 181884 | J15: 148023.4 | K15: 54066.01 | L15: 6692 | M15: 456384 | N15: 7041 | O15: 3048 | P15: 150149.35 | Q15: 0 | R15: 0 | S15: 15.199433 | T15: 0.472 | U15: 7.345 | V15: 0.0036549 | W15: 0 | X15: 11.344306 | Y15: 3.3958074 | Z15: 0.277587 | AA15: 12.235349 | AB15: 9.942678 | AC15: 0.2150142 | AD15: 0.0869122 | AE15: 0 | AF15: 8.4656111 | AG15: 203398.04
A16: 46087 | C16: 314116 | D16: 34735.53 | E16: 128737.54 | F16: 22419 | G16: 4635 | H16: 2105.588 | I16: 188512 | J16: 153677.6 | K16: 53292.92 | L16: 1581 | M16: 338950 | N16: 7043 | O16: 3050 | P16: 145897.5 | Q16: 0 | R16: 0 | S16: 15.270255 | T16: 0.473 | U16: 7.429 | V16: 0.0035456 | W16: 0 | X16: 11.338244 | Y16: 3.3965156 | Z16: 0.295975 | AA16: 12.281138 | AB16: 9.799064 | AC16: 0.2215297 | AD16: 0.0848442 | AE16: 0 | AF16: 8.4572564 | AG16: 199093.64
A17: 46088 | C17: 321649 | D17: 34678.44 | E17: 128069.74 | F17: 22854 | G17: 4564 | H17: 2093.258 | I17: 191030 | J17: 153188.6 | K17: 54466.46 | L17: 14718 | M17: 22364 | N17: 6926 | O17: 3205 | P17: 137582.38 | Q17: 0 | R17: 0 | S17: 15.353824 | T17: 0.467 | U17: 7.353 | V17: 0.0038068 | W17: 0 | X17: 11.342465 | Y17: 3.3885552 | Z17: 0.296579 | AA17: 11.48436 | AB17: 9.657937 | AC17: 0.2201133 | AD17: 0.0899433 | AE17: 0 | AF17: 8.2638908 | AG17: 189562.25
A18: 46089 | C18: 349458 | D18: 34578.92 | E18: 129553.43 | F18: 22796 | G18: 4590 | H18: 2091.809 | I18: 198546 | J18: 154892.7 | K18: 53080.71 | L18: 8639 | M18: 36007 | N18: 6942 | O18: 3125 | P18: 138992.07 | Q18: 0 | R18: 0 | S18: 16.28017 | T18: 0.466 | U18: 7.48 | V18: 0.0039206 | W18: 0 | X18: 11.344504 | Y18: 3.3865722 | Z18: 0.291647 | AA18: 11.496734 | AB18: 9.898404 | AC18: 0.2215297 | AD18: 0.0835411 | AE18: 0 | AF18: 8.3487595 | AG18: 191505.76
A19: 46090 | C19: 325538 | D19: 34619.16 | E19: 125988.88 | F19: 22747 | G19: 4468 | H19: 2097.157 | I19: 196616 | J19: 153563.9 | K19: 52248.79 | L19: 8310 | M19: 604 | N19: 6431 | O19: 3157 | P19: 135726.68 | Q19: 0 | R19: 0 | S19: 16.28272 | T19: 0.466 | U19: 7.472 | V19: 0.0037711 | W19: 0 | X19: 11.339632 | Y19: 3.3923796 | Z19: 0.287242 | AA19: 11.521795 | AB19: 9.843146 | AC19: 0.2167139 | AD19: 0.0880737 | AE19: 0 | AF19: 8.3363931 | AG19: 188162.59
A20: 46091 | C20: 328219 | D20: 34591.77 | E20: 127213.03 | F20: 22704 | G20: 4301 | H20: 2068.056 | I20: 200421 | J20: 154768 | K20: 51775.51 | L20: 9196 | M20: 0 | N20: 6553 | O20: 3111 | P20: 136798.2 | Q20: 0 | R20: 0 | S20: 15.972238 | T20: 0.464 | U20: 7.299 | V20: 0.0038487 | W20: 0 | X20: 11.35017 | Y20: 3.3831161 | Z20: 0.279686 | AA20: 11.502199 | AB20: 9.981722 | AC20: 0.2150142 | AD20: 0.0869972 | AE20: 0 | AF20: 8.3505784 | AG20: 189323.33
A21: 46092 | C21: 320631 | D21: 34217.36 | E21: 122359.65 | F21: 22732 | G21: 4303 | H21: 2013.681 | I21: 198485 | J21: 155699.3 | K21: 53413.51 | L21: 12860 | M21: 0 | N21: 6490 | O21: 3496 | P21: 137725.57 | Q21: 0 | R21: 0 | S21: 15.188952 | T21: 0.465 | U21: 7.275 | V21: 0.0039328 | W21: 0 | X21: 11.349717 | Y21: 3.3822096 | Z21: 0.270347 | AA21: 12.239116 | AB21: 10.014917 | AC21: 0.2212465 | AD21: 0.1039377 | AE21: 0 | AF21: 8.481846 | AG21: 191076.38
A22: 46093 | C22: 329031 | D22: 34097.98 | E22: 130171.67 | F22: 22753 | G22: 4334 | H22: 2039.245 | I22: 196523 | J22: 156015.3 | K22: 51578.9 | L22: 13829 | M22: 51079 | N22: 6714 | O22: 3311 | P22: 139471.6 | Q22: 0 | R22: 0 | S22: 15.358074 | T22: 0.463 | U22: 7.421 | V22: 0.0037424 | W22: 0 | X22: 11.354957 | Y22: 3.376034 | Z22: 0.275162 | AA22: 11.386072 | AB22: 10.132419 | AC22: 0.2246459 | AD22: 0.115949 | AE22: 0 | AF22: 8.3562346 | AG22: 192032.32
... A42: 46113 | C42: 314627 | D42: 33441.13 | E42: 139513.03 | F42: 22265.47 | G42: 4632 | H42: 1996.855 | I42: 191873 | J42: 157575.5 | K42: 54083.76 | L42: 10418 | M42: 147895 | N42: 6750 | O42: 3654 | P42: 141952.71 | Q42: 0 | R42: 0 | S42: 16.924929 | T42: 0.455 | U42: 7.624 | V42: 0.0036494 | W42: 0 | X42: 11.442068 | Y42: 3.3541926 | Z42: 0.289281 | AA42: 9.7985169 | AB42: 10.413885 | AC42: 0.1917847 | AD42: 0.0952408 | AE42: 0 | AF42: 8.1692979 | AG42: 193337.6
A43: Target : April 2026 | B43: BE | C43: 417857.14 | D43: 23880.247 | E43: 95761.494 | F43: 22140 | G43: 5424 | H43: 2021.3333 | I43: 140496.67 | J43: 174553.85 | K43: 52560 | L43: 13153.713 | M43: 431800 | N43: 7563.6363 | O43: 4927.5 | P43: 146425.33 | Q43: 0 | R43: 0 | S43: 14.430014 | T43: 0.24691357 | U43: 14.367816 | V43: 0.047619033 | W43: 0.066666667 | X43: 11.764706 | Y43: 3.5294118 | Z43: 0.26666667 | AA43: 8.5 | AB43: 8.4615385 | AC43: 0.3030303 | AD43: 0.16666667 | AE43: 0 | AF43: 7.3666667 | AG43: 192761.67
A44: Prod. : MTD Actual | B44: 46113 | C44: 314627 | D44: 33441.13 | E44: 139513.03 | F44: 22265.47 | G44: 4632 | H44: 1996.855 | I44: 191873 | J44: 157575.5 | K44: 54083.76 | L44: 10418 | M44: 147895 | N44: 6750 | O44: 3654 | P44: 141952.71 | Q44: 0 | R44: 0 | S44: 16.924929 | T44: 0.455 | U44: 7.624 | V44: 0.0036494 | W44: 0 | X44: 11.442068 | Y44: 3.3541926 | Z44: 0.289281 | AA44: 9.7985169 | AB44: 10.413885 | AC44: 0.1917847 | AD44: 0.0952408 | AE44: 0 | AF44: 8.1692979 | AG44: 193337.6
B45: 45748 | C45: 328151 | D45: 29305.36 | E45: 0 | F45: 26225.71 | G45: 4591 | H45: 2119.73 | I45: 156900 | J45: 170250.2 | K45: 49457.2 | L45: 9435 | M45: 412868 | N45: 7352 | O45: 4376 | P45: 149643.48 | Q45: 141.21 | R45: 63.5445 | S45: 13.794051 | T45: 0.468 | U45: 0 | V45: 0.0036807 | W45: 0 | X45: 8.7235694 | Y45: 3.7898867 | Z45: 0.268567 | AA45: 0 | AB45: 3.32622 | AC45: 0.1977337 | AD45: 0.0844476 | AE45: 0.326 | AF45: 3.995314 | AG45: 174837.55
A46: Prod. : Montly Actual | B46: 46082 | C46: 327125.87 | D46: 34001.327 | E46: 131344.15 | F46: 22632.308 | G46: 4983.7097 | H46: 2050.0931 | I46: 183213.9 | J46: 155070.35 | K46: 52460.577 | L46: 10517.129 | M46: 101605.55 | N46: 6858.5484 | O46: 3321.3226 | P46: 138198.74 | Q46: 0 | R46: 0 | S46: 15.302266 | T46: 0.45819355 | U46: 7.4984516 | V46: 0.0038451645 | W46: 0 | X46: 11.324482 | Y46: 3.3777008 | Z46: 0.28565419 | AA46: 10.127921 | AB46: 9.4401204 | AC46: 0.21472174 | AD46: 0.094470442 | AE46: 0 | AF46: 7.91784 | AG46: 188001.95
A47: Target : 2026 - 27 | B47: BE | C47: 414774.95 | D47: 23688.483 | E47: 110191.31 | F47: 22241.096 | G47: 5461.1507 | H47: 2097.4795 | I47: 139900.55 | J47: 174593.05 | K47: 52400 | L47: 13127.972 | M47: 431104.11 | N47: 7770.8592 | O47: 5220 | P47: 146458.04 | S47: 13.757932 | T47: 0.25367832 | U47: 4.7236656 | V47: 0.0039138932 | W47: 0.021917808 | X47: 10.829976 | Y47: 3.2554392 | Z47: 0.25753425 | AA47: 8.4794521 | AB47: 8.4299262 | AC47: 0.2241594 | AD47: 0.21917808 | AF47: 7.0630137 | AG47: 190884.4
A48: YTD Target : 2026 - 27 | B48: BE | C48: 417857.14 | D48: 23880.254 | E48: 95760.534 | F48: 22140 | G48: 5424 | H48: 2021.3359 | I48: 140496.68 | J48: 174553.84 | K48: 52560 | L48: 13153.723 | M48: 431800.06 | N48: 7563.6163 | O48: 4927.5 | P48: 146425.34 | Q48: 0 | R48: 0 | S48: 14.43 | T48: 0.246915 | U48: 14.367672 | V48: 0.047619 | W48: 0.066666 | X48: 11.764706 | Y48: 3.529412 | Z48: 0.266667 | AA48: 8.5 | AB48: 8.461538 | AC48: 0.303027 | AD48: 0.166668 | AE48: 0 | AF48: 7.366666 | AG48: 192761.67
A49: YTD Actual Prod. | B49: 2026 - 2027 | C49: 314627 | D49: 21270.191 | E49: 0 | F49: 22191.423 | G49: 4635.9645 | H49: 1994.902 | I49: 191873 | J49: 157532.33 | K49: 54075.249 | L49: 10417.974 | M49: 147450.23 | N49: 6760.5246 | O49: 3704.4478 | P49: 138281.27 | Q49: 0 | R49: 0 | S49: 16.796708 | T49: 0.455 | U49: 0 | V49: 0.0036551 | W49: 0.0280667 | X49: 11.442068 | Y49: 3.3541926 | Z49: 0.2891632 | AA49: 9.7983697 | AB49: 10.412736 | AC49: 0.1914632 | AD49: 0.0999132 | AE49: 0 | AF49: 8.1632847 | AG49: 189628.33
B50: 2025 - 2026 | C50: 328377.98 | D50: 27697.62 | E50: 0 | F50: 26225.693 | G50: 4591 | H50: 2090.5238 | I50: 1532569.3 | J50: 170266.24 | K50: 49390.928 | L50: 9434.958 | M50: 394559.39 | N50: 7352 | O50: 4376.2706 | P50: 423576.03 | Q50: 141.20857 | R50: 63.543855 | S50: 13.672566 | T50: 0.6010147 | U50: 0 | V50: 0.0036693 | W50: 0.0279 | X50: 8.7233132 | Y50: 3.9216776 | Z50: 0.2687277 | AA50: 9.1 | AB50: 3.3529873 | AC50: 0.1969462 | AD50: 0.1617072 | AE50: 0.4620322 | AF50: 5.9831295 | AG50: 461273.46
A51: Asking Rate : 2026 - 27 | B51: BE | C51: 415050.08 | D51: 23695.127 | E51: 110494.03 | F51: 22241.232 | G51: 5463.4177 | H51: 2097.7613 | I51: 139757.77 | J51: 174639.92 | K51: 52395.398 | L51: 13135.417 | M51: 431883.38 | N51: 7773.6348 | O51: 5224.1636 | P51: 146480.5 | Q51: - | R51: - | S51: 13.749583 | T51: 0.25312524 | U51: 4.7366427 | V51: 0.003914604 | W51: 0.021900916 | X51: 10.828294 | Y51: 3.2551679 | Z51: 0.25744735 | AA51: 8.4758287 | AB51: 8.424479 | AC51: 0.22424922 | AD51: 0.21950573 | AE51: - | AF51: 7.059991 | AG51: 190887.85
A52: Actual Prod. : 2025 - 26 | C52: 328625.64 | D52: 23919.884 | E52: 106999.64 | F52: 21202.661 | G52: 4841.0219 | H52: 2167.599 | I52: 142979.54 | J52: 164252.25 | K52: 46000.399 | L52: 10490.511 | M52: 390201.05 | N52: 6663.7836 | O52: 4169.6986 | P52: 139007.28 | Q52: 154.78995 | R52: 69.655475 | S52: 11.946063 | T52: 0.33110685 | U52: 4.5433745 | V52: 0.0035041121 | W52: 0.02936165 | X52: 10.792748 | Y52: 3.19798 | Z52: 0.27551233 | AA52: 8.5286685 | AB52: 10.164757 | AC52: 0.19652854 | AD52: 0.090606776 | AE52: 0.28355617 | AF52: 7.6509402 | AG52: 187201.34
A53: Consortium Level | C53: ONGC Videsh
A54: Unit | C54: MMT | Q54: MMT | S54: BCM | AG54: MMTOE
A55: Target : 2026 - 27 | B55: BE | C55: 0.471 | D55: 0.35 | E55: 0.014 | F55: 0.77 | G55: 0.147 | H55: 0.101 | I55: 1.369 | J55: 2.227 | K55: 0.655 | L55: 0.17 | M55: 0.826 | N55: 0.05 | O55: 0.116 | P55: 7.266 | S55: 0.116 | T55: 0.025 | U55: 0.004 | V55: 0.001 | W55: 0.004 | X55: 0.672 | Y55: 0.202 | Z55: 0.094 | AA55: 0.619 | AB55: 0.8 | AC55: 0.009 | AD55: 0.032 | AF55: 2.578 | AG55: 9.844
A56: YTD Target : 2026 - 27 | B56: BE | C56: 0.0013 | D56: 0.000966667 | E56: 3.3333e-05 | F56: 0.0021 | G56: 0.0004 | H56: 0.000266667 | I56: 0.003766667 | J56: 0.0061 | K56: 0.0018 | L56: 0.000466667 | M56: 0.002266667 | N56: 0.000133333 | O56: 0.0003 | P56: 0.019900001 | S56: 0.000333333 | T56: 6.6667e-05 | U56: 3.3333e-05 | V56: 3.3333e-05 | W56: 3.3333e-05 | X56: 0.002 | Y56: 0.0006 | Z56: 0.000266667 | AA56: 0.0017 | AB56: 0.0022 | AC56: 3.3333e-05 | AD56: 6.6667e-05 | AF56: 0.007366666 | AG56: 0.027266667
A57: YTD Actual Prod.: 2026 - 27 | C57: 0.0012369408 | D57: 0.00086165803 | E57: 0 | F57: 0.002105777 | G57: 0.00034187898 | H57: 0.00025805033 | I57: 0.0052401408 | J57: 0.0055051621 | K57: 0.0018518921 | L57: 0.00036960826 | M57: 0.00077401695 | N57: 0.0001191759 | O57: 0.00022553705 | P57: 0.018889838 | Q57: 0 | R57: 0 | S57: 0.0004913037 | T57: 0 | U57: 0 | V57: 2.5586e-06 | W57: 1.40334e-05 | X57: 0.0019451516 | Y57: 0.0005702127 | Z57: 0.0002891632 | AA57: 0.0019596739 | AB57: 0.0027073113 | AC57: 2.1061e-05 | AD57: 3.99653e-05 | AE57: 0 | AF57: 0.0080404347 | AG57: 0.026930273
A58: % Achiev. wrt YTD Target | B58: BE | C58: 95.149294 | D58: 89.137007 | E58: 0 | F58: 100.2751 | G58: 85.469746 | H58: 96.768752 | I58: 139.11877 | J58: 90.248559 | K58: 102.88289 | L58: 79.201713 | M58: 34.147801 | N58: 89.382149 | O58: 75.179016 | P58: 94.923806 | S58: 147.39126 | T58: 0 | U58: 0 | V58: 7.6758768 | W58: 42.100621 | X58: 97.25758 | Y58: 95.03545 | Z58: 108.43606 | AA58: 115.27494 | AB58: 123.0596 | AC58: 63.183632 | AD58: 59.94765 | AF58: 109.14618 | AG58: 98.766282
A59: % Achiev. wrt Yearly Target | B59: BE | C59: 0.26262013 | D59: 0.24618801 | E59: 0 | F59: 0.27347754 | G59: 0.23257074 | H59: 0.25549537 | I59: 0.38277143 | J59: 0.24720081 | K59: 0.28273162 | L59: 0.21741662 | M59: 0.093706652 | N59: 0.2383518 | O59: 0.19442849 | P59: 0.25997576 | S59: 0.42353767 | T59: 0 | U59: 0 | V59: 0.25586 | W59: 0.350835 | X59: 0.28945708 | Y59: 0.28228351 | Z59: 0.30762043 | AA59: 0.31658706 | AB59: 0.33841391 | AC59: 0.23401111 | AD59: 0.12489156 | AF59: 0.31188653 | AG59: 0.27357043
A60: Actual Production | B60: 2021 - 22 | C60: 0.50574824 | D60: 0.45265178 | E60: 0 | F60: 0.44315559 | G60: 0.21914233 | H60: 0.186576 | I60: 2.1855635 | J60: 2.6806081 | K60: 0.27796588 | L60: 0.021216536 | M60: 0.7276962 | N60: 0.059716879 | O60: 0.05250668 | P60: 7.8125477 | Q60: 0.00725535 | R60: 0.00725535 | S60: 0.099531064 | T60: 0.031174472 | U60: 0 | V60: 0.0009464043 | W60: 0.0069834336 | X60: 0.61933887 | Y60: 0.27731972 | Z60: 0.100275 | AA60: 0.70981551 | AB60: 1.4684397 | AC60: 0.0048819468 | AD60: 0.0085768154 | AE60: 0.53936415 | AF60: 3.8666471 | AG60: 11.68645
B61: 2022 - 23 | C61: 0.45862536 | D61: 0.34662771 | E61: 0 | F61: 0.65409551 | G61: 0.077207053 | H61: 0.169166 | I61: 0.16111269 | J61: 2.4631688 | K61: 0.24375485 | L61: 0.05769997 | M61: 1.1035464 | N61: 0.057970124 | O61: 0.05286492 | P61: 5.8458394 | Q61: 0.00529605 | R61: 0.00529605 | S61: 0.079138956 | T61: 0.02186352 | U61: 0 | V61: 0.0016170035 | W61: 0.0023245111 | X61: 0.71853372 | Y61: 0.2330016 | Z61: 0.11770501 | AA61: 0.6102468 | AB61: 1.1435139 | AC61: 0.0066903684 | AD61: 0.0081769977 | AE61: 0.68836905 | AF61: 3.6311814 | AG61: 9.4823168
B62: 2023 - 24 | C62: 0.4 | D62: 0.39 | E62: 0 | F62: 0.66012031 | G62: 0.086 | H62: 0.124 | I62: 1.684 | J62: 2.317 | K62: 0.583 | L62: 0.076 | M62: 0.724 | N62: 0.056 | O62: 0.075 | P62: 7.1751203 | Q62: 0.003 | R62: 0.003 | S62: 0.082 | T62: 0.029 | U62: 0 | V62: 0.001 | W62: 0.003 | X62: 0.655 | Y62: 0.178 | Z62: 0.114 | AA62: 0.701 | AB62: 1.138 | AC62: 0.008 | AD62: 0.013 | AE62: 0.418 | AF62: 3.34 | AG62: 10.51812
...

Sheet 2
B2: Production Date | C2: 01.MAR.2026 | D2: 02.MAR.2026 | E2: 03.MAR.2026 | F2: 04.MAR.2026 | G2: 05.MAR.2026 | H2: 06.MAR.2026 | I2: 07.MAR.2026 | J2: 08.MAR.2026 | K2: 09.MAR.2026 | L2: 10.MAR.2026 | M2: 11.MAR.2026 | N2: 12.MAR.2026 | O2: 13.MAR.2026 | P2: 14.MAR.2026 | Q2: 15.MAR.2026 | R2: 16.MAR.2026 | S2: 17.MAR.2026 | T2: 18.MAR.2026 | U2: 19.MAR.2026 | V2: 20.MAR.2026 | W2: 21.MAR.2026 | X2: 22.MAR.2026 | Y2: 23.MAR.2026 | Z2: 24.MAR.2026 | AA2: 25.MAR.2026 | AB2: 26.MAR.2026 | AC2: 27.MAR.2026 | AD2: 28.MAR.2026 | AE2: 29.MAR.2026 | AF2: 30.MAR.2026 | AG2: 31.MAR.2026 | AH2: 01.APR.2026
B3: Actual Production | C3: 203846.99 | D3: 193740.47 | E3: 193691.39 | F3: 190504.14 | G3: 203398.04 | H3: 199093.64 | I3: 189562.25 | J3: 191505.76 | K3: 188162.59 | L3: 189323.33 | M3: 191076.38 | N3: 192032.32 | O3: 186729.17 | P3: 189084.12 | Q3: 181665.48 | R3: 183010.55 | S3: 181127.72 | T3: 181533.96 | U3: 183335.54 | V3: 183808.45 | W3: 182738.2 | X3: 180976.68 | Y3: 183026.59 | Z3: 181172.44 | AA3: 189230.26 | AB3: 183469.64 | AC3: 184363.41 | AD3: 187318.16 | AE3: 184338.5 | AF3: 188935.76 | AG3: 186258.48 | AH3: 193337.6
B4: BE Target | C4: 190884.4 | D4: 190884.4 | E4: 190884.4 | F4: 190884.4 | G4: 190884.4 | H4: 190884.4 | I4: 190884.4 | J4: 190884.4 | K4: 190884.4 | L4: 190884.4 | M4: 190884.4 | N4: 190884.4 | O4: 190884.4 | P4: 190884.4 | Q4: 190884.4 | R4: 190884.4 | S4: 190884.4 | T4: 190884.4 | U4: 190884.4 | V4: 190884.4 | W4: 190884.4 | X4: 190884.4 | Y4: 190884.4 | Z4: 190884.4 | AA4: 190884.4 | AB4: 190884.4 | AC4: 190884.4 | AD4: 190884.4 | AE4: 190884.4 | AF4: 190884.4 | AG4: 190884.4 | AH4: 190884.4

Sheet Production Performance
A45: ONGC Videsh2026-27 | B45: Oil, LNG & Condensate ( BOPD ) | D45: Gas ( MMSCMD ) | F45: Total (O+OEG) ( BOEPD )
B46: Annual | C46: YTD | D46: Annual | E46: YTD | F46: Annual | G46: YTD
A47: Actual | B47: - | C47: ='DPR ( 02-APR-2026 )'!P49 -> 138281.27 | D47: - | E47: ='DPR ( 02-APR-2026 )'!AF49 -> 8.1632847 | F47: - | G47: ='DPR ( 02-APR-2026 )'!AG49 -> 189628.33
A48: BE Target | B48: ='DPR ( 02-APR-2026 )'!P47 -> 146458.04 | C48: ='DPR ( 02-APR-2026 )'!P48 -> 146425.34 | D48: ='DPR ( 02-APR-2026 )'!AF47 -> 7.0630137 | E48: ='DPR ( 02-APR-2026 )'!AF48 -> 7.366666 | F48: ='DPR ( 02-APR-2026 )'!AG47 -> 190884.4 | G48: ='DPR ( 02-APR-2026 )'!AG48 -> 192761.67
A49: % Achv w.r.t. BE Target | C49: 94.438074 | E49: 110.81383 | G49: 98.374502
